Workbook

Sheet Routine hebdo 5min
B1: ⚡ ROUTINE HEBDOMADAIRE — 5 MINUTES CHRONO
B2: À faire chaque lundi matin · Cochez les cases au fur et à mesure
B5: ÉTAPE 1 · 1 min · 📥 SAISIR les commandes de la semaine
B6: ☐ | C6: Dans 'Historique commandes' : ajouter Date, Jour, Restaurant, Montant brut, Réduction, Frais livraison, Heure, Code promo utilisé.
C7: 💡 Le Score et le Verdict se calculent automatiquement
B9: ÉTAPE 2 · 1 min · 🎁 VÉRIFIER les promos qui expirent
B10: ☐ | C10: Dans 'Suivi promotions' : regarder colonne 'Expire le' surlignée en jaune (≤3 jours). Planifier une commande avant expiration si la promo vaut le coup.
C11: 💡 Les promos expirées s'affichent en rouge automatiquement
B13: ÉTAPE 3 · 1 min · ➕ SAISIR les nouvelles promos reçues
B14: ☐ | C14: Notifs push Grab cette semaine → les ajouter dans 'Suivi promotions' avec code, valeur, condition, date d'expiration. Changer 'Utilisé ?' en Oui quand utilisée.
C15: 💡 Sources à vérifier : notifs app, email, widget app
B17: ÉTAPE 4 · 1 min · 📊 LIRE le Dashboard
B18: ☐ | C18: Vérifier : Score moyen (vert ≥8 / jaune 5-7 / rouge <5), Budget restant du mois, Nb promos disponibles non utilisées, Recommandation abonnement.
C19: 💡 Si score moyen < 5 → consulter 'Simulateur scénarios' pour ajuster
B21: ÉTAPE 5 · 1 min · 🎯 PLANIFIER la semaine suivante
B22: ☐ | C22: Regarder 'Analyse Grab' → section 'Dois-je commander maintenant ?' pour les meilleurs créneaux. Identifier 1-2 jours optimaux basés sur tes patterns. Prévoir d'utiliser tes promos avant expiration.
C23: 💡 Meilleurs créneaux Grab : 14h-17h (Happy Hour) et hors 12h-13h / 19h-20h
B25: RÉCAPITULATIF AUTOMATIQUE DE LA SEMAINE
B26: Commandes cette semaine | E26: =COUNTIFS('Historique commandes'!A3:A52,">="&TODAY()-7,'Historique commandes'!C3:C52,"Grab")
B27: Dépensé cette semaine (Grab) | E27: =SUMPRODUCT(('Historique commandes'!A3:A52>=TODAY()-7)*('Historique commandes'!C3:C52="Grab")*IFERROR('Historique commandes'!H3:H52,0))
B28: Économisé cette semaine (Grab) | E28: =ABS(SUMPRODUCT(('Historique commandes'!A3:A52>=TODAY()-7)*('Historique commandes'!C3:C52="Grab")*IFERROR('Historique commandes'!F3:F52,0)))
B29: Score moyen cette semaine | E29: =IFERROR(AVERAGEIFS('Historique commandes'!K3:K52,'Historique commandes'!A3:A52,">="&TODAY()-7,'Historique commandes'!C3:C52,"Grab"),0)
B30: Promos Grab non utilisées | E30: =COUNTIFS('Suivi promotions'!A3:A40,"Grab",'Suivi promotions'!G3:G40,"Non",'Suivi promotions'!F3:F40,">="&TODAY())
B31: Budget restant ce mois | E31: =Dashboard!D30

Sheet Dashboard
B1: 📊 DASHBOARD — OPTIMISATION LIVRAISON
B2: Mis à jour automatiquement — Données de Historique commandes
B4: KPIs GLOBAUX
B5: Total dépensé (€) | E5: ='Historique commandes'!H54
B6: Total économisé (€) | E6: =ABS('Historique commandes'!F54)+ABS('Historique commandes'!G54)-SUMPRODUCT(('Historique commandes'!G3:G52>0)*('Historique commandes'!G3:G52))
B7: Taux de réduction moyen | E7: =IFERROR(ABS('Historique commandes'!F54)/'Historique commandes'!E54,0)
B8: Nb de commandes | E8: =COUNTA('Historique commandes'!A3:A52)
B9: Panier moyen (€) | E9: =IFERROR('Historique commandes'!E54/C8,0)
B10: Frais livraison payés (€) | E10: ='Historique commandes'!G54
B11: Score moyen d'optimisation /10 | E11: =IFERROR(AVERAGEIF('Historique commandes'!K3:K52,">0",'Historique commandes'!K3:K52),0)
B13: ANALYSE PAR PLATEFORME
B14: Plateforme | C14: Nb commandes | D14: Total dépensé (€) | E14: Économies (€) | F14: Livraison payée (€)
B15: Grab | C15: =COUNTIF('Historique commandes'!C3:C52,"Grab") | D15: =SUMIF('Historique commandes'!C3:C52,"Grab",'Historique commandes'!H3:H52) | E15: =ABS(SUMIF('Historique commandes'!C3:C52,"Grab",'Historique commandes'!F3:F52)) | F15: =SUMIF('Historique commandes'!C3:C52,"Grab",'Historique commandes'!G3:G52)
B16: Wolt | C16: =COUNTIF('Historique commandes'!C3:C52,"Wolt") | D16: =SUMIF('Historique commandes'!C3:C52,"Wolt",'Historique commandes'!H3:H52) | E16: =ABS(SUMIF('Historique commandes'!C3:C52,"Wolt",'Historique commandes'!F3:F52)) | F16: =SUMIF('Historique commandes'!C3:C52,"Wolt",'Historique commandes'!G3:G52)
B17: Autres | C17: =COUNTIF('Historique commandes'!C3:C52,"Autres") | D17: =SUMIF('Historique commandes'!C3:C52,"Autres",'Historique commandes'!H3:H52) | E17: =ABS(SUMIF('Historique commandes'!C3:C52,"Autres",'Historique commandes'!F3:F52)) | F17: =SUMIF('Historique commandes'!C3:C52,"Autres",'Historique commandes'!G3:G52)
B20: INDICATEURS & RECOMMANDATIONS
B21: Abonnement Wolt+ rentable ? | E21: =IF(SUMIF('Historique commandes'!C3:C52,"Wolt",'Historique commandes'!G3:G52)>3.99,"✅ OUI — économie vs 3.99€/mois","❌ NON — commandes Wolt insuffisantes")
B22: Abonnement Grab Unlimited ? | E22: =IF(SUMIF('Historique commandes'!C3:C52,"Grab",'Historique commandes'!G3:G52)>5.99,"✅ OUI — économie vs 5.99€/mois","❌ NON — commandes Grab insuffisantes")
B23: Promos disponibles non utilisées | E23: =COUNTIFS('Suivi promotions'!G3:G40,"Non",'Suivi promotions'!F3:F40,">="&TODAY())&" promo(s) active(s) à exploiter"
B24: Promos expirées non utilisées | E24: =COUNTIFS('Suivi promotions'!G3:G40,"Non",'Suivi promotions'!F3:F40,"<"&TODAY())&" promo(s) manquée(s)"
B27: OBJECTIF MENSUEL
B28: Budget mensuel cible (€) | D28: 200
B29: Dépensé ce mois (€) | D29: ='Historique commandes'!H54
B30: Reste du budget (€) | D30: =D28-D29

Sheet Analyse Grab
B1: 🟢 ANALYSE GRAB — PATTERNS & OPTIMISATION
B2: Données filtrées automatiquement sur Grab · Mis à jour en temps réel
B4: KPIs GRAB
B5: Nb de commandes Grab | E5: =COUNTIF('Historique commandes'!C3:C52,"Grab")
B6: Total dépensé Grab (€) | E6: =SUMIF('Historique commandes'!C3:C52,"Grab",'Historique commandes'!H3:H52)
B7: Panier moyen Grab (€) | E7: =IFERROR(SUMIF('Historique commandes'!C3:C52,"Grab",'Historique commandes'!E3:E52)/COUNTIF('Historique commandes'!C3:C52,"Grab"),0)
B8: Économies totales Grab (€) | E8: =ABS(SUMIF('Historique commandes'!C3:C52,"Grab",'Historique commandes'!F3:F52))
B9: Frais livraison Grab (€) | E9: =SUMIF('Historique commandes'!C3:C52,"Grab",'Historique commandes'!G3:G52)
B10: Taux promo utilisé | E10: =IFERROR(COUNTIFS('Historique commandes'!C3:C52,"Grab",'Historique commandes'!I3:I52,"<>")/COUNTIF('Historique commandes'!C3:C52,"Grab"),0)
B11: Score moyen optimisation | E11: =IFERROR(AVERAGEIF('Historique commandes'!C3:C52,"Grab",'Historique commandes'!K3:K52),0)
B14: PATTERNS — MEILLEURS JOURS GRAB
B15: Jour | C15: Nb commandes | D15: Panier moyen (€) | E15: Économie moy. (€) | F15: % avec promo | G15: Score moyen
B16: Lundi | C16: =COUNTIFS('Historique commandes'!C3:C52,"Grab",'Historique commandes'!B3:B52,"Lun") | D16: =IFERROR(AVERAGEIFS('Historique commandes'!E3:E52,'Historique commandes'!C3:C52,"Grab",'Historique commandes'!B3:B52,"Lun"),"-") | E16: =IFERROR(ABS(AVERAGEIFS('Historique commandes'!F3:F52,'Historique commandes'!C3:C52,"Grab",'Historique commandes'!B3:B52,"Lun",'Historique commandes'!F3:F52,"<0")),0) | F16: =IFERROR(COUNTIFS('Historique commandes'!C3:C52,"Grab",'Historique commandes'!B3:B52,"Lun",'Historique commandes'!I3:I52,"<>")/C16,0) | G16: =IFERROR(AVERAGEIFS('Historique commandes'!K3:K52,'Historique commandes'!C3:C52,"Grab",'Historique commandes'!B3:B52,"Lun"),"-")
B17: Mardi | C17: =COUNTIFS('Historique commandes'!C3:C52,"Grab",'Historique commandes'!B3:B52,"Mar") | D17: =IFERROR(AVERAGEIFS('Historique commandes'!E3:E52,'Historique commandes'!C3:C52,"Grab",'Historique commandes'!B3:B52,"Mar"),"-") | E17: =IFERROR(ABS(AVERAGEIFS('Historique commandes'!F3:F52,'Historique commandes'!C3:C52,"Grab",'Historique commandes'!B3:B52,"Mar",'Historique commandes'!F3:F52,"<0")),0) | F17: =IFERROR(COUNTIFS('Historique commandes'!C3:C52,"Grab",'Historique commandes'!B3:B52,"Mar",'Historique commandes'!I3:I52,"<>")/C17,0) | G17: =IFERROR(AVERAGEIFS('Historique commandes'!K3:K52,'Historique commandes'!C3:C52,"Grab",'Historique commandes'!B3:B52,"Mar"),"-")
B18: Mercredi | C18: =COUNTIFS('Historique commandes'!C3:C52,"Grab",'Historique commandes'!B3:B52,"Mer") | D18: =IFERROR(AVERAGEIFS('Historique commandes'!E3:E52,'Historique commandes'!C3:C52,"Grab",'Historique commandes'!B3:B52,"Mer"),"-") | E18: =IFERROR(ABS(AVERAGEIFS('Historique commandes'!F3:F52,'Historique commandes'!C3:C52,"Grab",'Historique commandes'!B3:B52,"Mer",'Historique commandes'!F3:F52,"<0")),0) | F18: =IFERROR(COUNTIFS('Historique commandes'!C3:C52,"Grab",'Historique commandes'!B3:B52,"Mer",'Historique commandes'!I3:I52,"<>")/C18,0) | G18: =IFERROR(AVERAGEIFS('Historique commandes'!K3:K52,'Historique commandes'!C3:C52,"Grab",'Historique commandes'!B3:B52,"Mer"),"-")
B19: Jeudi | C19: =COUNTIFS('Historique commandes'!C3:C52,"Grab",'Historique commandes'!B3:B52,"Jeu") | D19: =IFERROR(AVERAGEIFS('Historique commandes'!E3:E52,'Historique commandes'!C3:C52,"Grab",'Historique commandes'!B3:B52,"Jeu"),"-") | E19: =IFERROR(ABS(AVERAGEIFS('Historique commandes'!F3:F52,'Historique commandes'!C3:C52,"Grab",'Historique commandes'!B3:B52,"Jeu",'Historique commandes'!F3:F52,"<0")),0) | F19: =IFERROR(COUNTIFS('Historique commandes'!C3:C52,"Grab",'Historique commandes'!B3:B52,"Jeu",'Historique commandes'!I3:I52,"<>")/C19,0) | G19: =IFERROR(AVERAGEIFS('Historique commandes'!K3:K52,'Historique commandes'!C3:C52,"Grab",'Historique commandes'!B3:B52,"Jeu"),"-")
B20: Vendredi | C20: =COUNTIFS('Historique commandes'!C3:C52,"Grab",'Historique commandes'!B3:B52,"Ven") | D20: =IFERROR(AVERAGEIFS('Historique commandes'!E3:E52,'Historique commandes'!C3:C52,"Grab",'Historique commandes'!B3:B52,"Ven"),"-") | E20: =IFERROR(ABS(AVERAGEIFS('Historique commandes'!F3:F52,'Historique commandes'!C3:C52,"Grab",'Historique commandes'!B3:B52,"Ven",'Historique commandes'!F3:F52,"<0")),0) | F20: =IFERROR(COUNTIFS('Historique commandes'!C3:C52,"Grab",'Historique commandes'!B3:B52,"Ven",'Historique commandes'!I3:I52,"<>")/C20,0) | G20: =IFERROR(AVERAGEIFS('Historique commandes'!K3:K52,'Historique commandes'!C3:C52,"Grab",'Historique commandes'!B3:B52,"Ven"),"-")
B21: Samedi | C21: =COUNTIFS('Historique commandes'!C3:C52,"Grab",'Historique commandes'!B3:B52,"Sam") | D21: =IFERROR(AVERAGEIFS('Historique commandes'!E3:E52,'Historique commandes'!C3:C52,"Grab",'Historique commandes'!B3:B52,"Sam"),"-") | E21: =IFERROR(ABS(AVERAGEIFS('Historique commandes'!F3:F52,'Historique commandes'!C3:C52,"Grab",'Historique commandes'!B3:B52,"Sam",'Historique commandes'!F3:F52,"<0")),0) | F21: =IFERROR(COUNTIFS('Historique commandes'!C3:C52,"Grab",'Historique commandes'!B3:B52,"Sam",'Historique commandes'!I3:I52,"<>")/C21,0) | G21: =IFERROR(AVERAGEIFS('Historique commandes'!K3:K52,'Historique commandes'!C3:C52,"Grab",'Historique commandes'!B3:B52,"Sam"),"-")
B22: Dimanche | C22: =COUNTIFS('Historique commandes'!C3:C52,"Grab",'Historique commandes'!B3:B52,"Dim") | D22: =IFERROR(AVERAGEIFS('Historique commandes'!E3:E52,'Historique commandes'!C3:C52,"Grab",'Historique commandes'!B3:B52,"Dim"),"-") | E22: =IFERROR(ABS(AVERAGEIFS('Historique commandes'!F3:F52,'Historique commandes'!C3:C52,"Grab",'Historique commandes'!B3:B52,"Dim",'Historique commandes'!F3:F52,"<0")),0) | F22: =IFERROR(COUNTIFS('Historique commandes'!C3:C52,"Grab",'Historique commandes'!B3:B52,"Dim",'Historique commandes'!I3:I52,"<>")/C22,0) | G22: =IFERROR(AVERAGEIFS('Historique commandes'!K3:K52,'Historique commandes'!C3:C52,"Grab",'Historique commandes'!B3:B52,"Dim"),"-")
B25: PATTERNS — CRÉNEAUX HORAIRES GRAB
B26: Créneau | C26: Nb commandes | D26: Panier moyen (€) | E26: Économie moy. (€) | F26: % avec promo | G26: Recommandation
B27: 🌅 Matin (7h-11h) | C27: =SUMPRODUCT(('Historique commandes'!C3:C52="Grab")*('Historique commandes'!M3:M52<>"")*(VALUE(LEFT('Historique commandes'!M3:M52,2))>=7)*(VALUE(LEFT('Historique commandes'!M3:M52,2))<11)) | D27: =IFERROR(SUMPRODUCT(('Historique commandes'!C3:C52="Grab")*('Historique commandes'!M3:M52<>"")*(VALUE(LEFT('Historique commandes'!M3:M52,2))>=7)*(VALUE(LEFT('Historique commandes'!M3:M52,2))<11)*'Historique commandes'!E3:E52)/=SUMPRODUCT(('Historique commandes'!C3:C52="Grab")*('Historique commandes'!M3:M52<>"")*(VALUE(LEFT('Historique commandes'!M3:M52,2))>=7)*(VALUE(LEFT('Historique commandes'!M3:M52,2))<11)),"-") | E27: =IFERROR(ABS(SUMPRODUCT(('Historique commandes'!C3:C52="Grab")*('Historique commandes'!M3:M52<>"")*(VALUE(LEFT('Historique commandes'!M3:M52,2))>=7)*(VALUE(LEFT('Historique commandes'!M3:M52,2))<11)*('Historique commandes'!F3:F52<0)*'Historique commandes'!F3:F52))/=SUMPRODUCT(('Historique commandes'!C3:C52="Grab")*('Historique commandes'!M3:M52<>"")*(VALUE(LEFT('Historique commandes'!M3:M52,2))>=7)*(VALUE(LEFT('Historique commandes'!M3:M52,2))<11)),0) | F27: =IFERROR(SUMPRODUCT(('Historique commandes'!C3:C52="Grab")*('Historique commandes'!M3:M52<>"")*(VALUE(LEFT('Historique commandes'!M3:M52,2))>=7)*(VALUE(LEFT('Historique commandes'!M3:M52,2))<11)*('Historique commandes'!I3:I52<>""))/=SUMPRODUCT(('Historique commandes'!C3:C52="Grab")*('Historique commandes'!M3:M52<>"")*(VALUE(LEFT('Historique commandes'!M3:M52,2))>=7)*(VALUE(LEFT('Historique commandes'!M3:M52,2))<11)),0) | G27: =IF(=SUMPRODUCT(('Historique commandes'!C3:C52="Grab")*('Historique commandes'!M3:M52<>"")*(VALUE(LEFT('Historique commandes'!M3:M52,2))>=7)*(VALUE(LEFT('Historique commandes'!M3:M52,2))<11))=0,"— Pas encore de données",IF(AND(=IFERROR(SUMPRODUCT(('Historique commandes'!C3:C52="Grab")*('Historique commandes'!M3:M52<>"")*(VALUE(LEFT('Historique commandes'!M3:M52,2))>=7)*(VALUE(LEFT('Historique commandes'!M3:M52,2))<11)*'Historique commandes'!E3:E52)/=SUMPRODUCT(('Historique commandes'!C3:C52="Grab")*('Historique commandes'!M3:M52<>"")*(VALUE(LEFT('Historique commandes'!M3:M52,2))>=7)*(VALUE(LEFT('Historique commandes'!M3:M52,2))<11)),"-")<AVERAGEIF('Historique commandes'!C3:C52,"Grab",'Historique commandes'!E3:E52),=IFERROR(SUMPRODUCT(('Historique commandes'!C3:C52="Grab")*('Historique commandes'!M3:M52<>"")*(VALUE(LEFT('Historique commandes'!M3:M52,2))>=7)*(VALUE(LEFT('Historique commandes'!M3:M52,2))<11)*('Historique commandes'!I3:I52<>""))/=SUMPRODUCT(('Historique commandes'!C3:C52="Grab")*('Historique commandes'!M3:M52<>"")*(VALUE(LEFT('Historique commandes'!M3:M52,2))>=7)*(VALUE(LEFT('Historique commandes'!M3:M52,2))<11)),0)>0.5),"✅ Créneau optimal",IF(=IFERROR(SUMPRODUCT(('Historique commandes'!C3:C52="Grab")*('Historique commandes'!M3:M52<>"")*(VALUE(LEFT('Historique commandes'!M3:M52,2))>=7)*(VALUE(LEFT('Historique commandes'!M3:M52,2))<11)*'Historique commandes'!E3:E52)/=SUMPRODUCT(('Historique commandes'!C3:C52="Grab")*('Historique commandes'!M3:M52<>"")*(VALUE(LEFT('Historique commandes'!M3:M52,2))>=7)*(VALUE(LEFT('Historique commandes'!M3:M52,2))<11)),"-")>AVERAGEIF('Historique commandes'!C3:C52,"Grab",'Historique commandes'!E3:E52)*1.1,"⚠️ Éviter si possible","🟡 Correct")))
B28: ☀️ Midi (11h-14h) | C28: =SUMPRODUCT(('Historique commandes'!C3:C52="Grab")*('Historique commandes'!M3:M52<>"")*(VALUE(LEFT('Historique commandes'!M3:M52,2))>=11)*(VALUE(LEFT('Historique commandes'!M3:M52,2))<14)) | D28: =IFERROR(SUMPRODUCT(('Historique commandes'!C3:C52="Grab")*('Historique commandes'!M3:M52<>"")*(VALUE(LEFT('Historique commandes'!M3:M52,2))>=11)*(VALUE(LEFT('Historique commandes'!M3:M52,2))<14)*'Historique commandes'!E3:E52)/=SUMPRODUCT(('Historique commandes'!C3:C52="Grab")*('Historique commandes'!M3:M52<>"")*(VALUE(LEFT('Historique commandes'!M3:M52,2))>=11)*(VALUE(LEFT('Historique commandes'!M3:M52,2))<14)),"-") | E28: =IFERROR(ABS(SUMPRODUCT(('Historique commandes'!C3:C52="Grab")*('Historique commandes'!M3:M52<>"")*(VALUE(LEFT('Historique commandes'!M3:M52,2))>=11)*(VALUE(LEFT('Historique commandes'!M3:M52,2))<14)*('Historique commandes'!F3:F52<0)*'Historique commandes'!F3:F52))/=SUMPRODUCT(('Historique commandes'!C3:C52="Grab")*('Historique commandes'!M3:M52<>"")*(VALUE(LEFT('Historique commandes'!M3:M52,2))>=11)*(VALUE(LEFT('Historique commandes'!M3:M52,2))<14)),0) | F28: =IFERROR(SUMPRODUCT(('Historique commandes'!C3:C52="Grab")*('Historique commandes'!M3:M52<>"")*(VALUE(LEFT('Historique commandes'!M3:M52,2))>=11)*(VALUE(LEFT('Historique commandes'!M3:M52,2))<14)*('Historique commandes'!I3:I52<>""))/=SUMPRODUCT(('Historique commandes'!C3:C52="Grab")*('Historique commandes'!M3:M52<>"")*(VALUE(LEFT('Historique commandes'!M3:M52,2))>=11)*(VALUE(LEFT('Historique commandes'!M3:M52,2))<14)),0) | G28: =IF(=SUMPRODUCT(('Historique commandes'!C3:C52="Grab")*('Historique commandes'!M3:M52<>"")*(VALUE(LEFT('Historique commandes'!M3:M52,2))>=11)*(VALUE(LEFT('Historique commandes'!M3:M52,2))<14))=0,"— Pas encore de données",IF(AND(=IFERROR(SUMPRODUCT(('Historique commandes'!C3:C52="Grab")*('Historique commandes'!M3:M52<>"")*(VALUE(LEFT('Historique commandes'!M3:M52,2))>=11)*(VALUE(LEFT('Historique commandes'!M3:M52,2))<14)*'Historique commandes'!E3:E52)/=SUMPRODUCT(('Historique commandes'!C3:C52="Grab")*('Historique commandes'!M3:M52<>"")*(VALUE(LEFT('Historique commandes'!M3:M52,2))>=11)*(VALUE(LEFT('Historique commandes'!M3:M52,2))<14)),"-")<AVERAGEIF('Historique commandes'!C3:C52,"Grab",'Historique commandes'!E3:E52),=IFERROR(SUMPRODUCT(('Historique commandes'!C3:C52="Grab")*('Historique commandes'!M3:M52<>"")*(VALUE(LEFT('Historique commandes'!M3:M52,2))>=11)*(VALUE(LEFT('Historique commandes'!M3:M52,2))<14)*('Historique commandes'!I3:I52<>""))/=SUMPRODUCT(('Historique commandes'!C3:C52="Grab")*('Historique commandes'!M3:M52<>"")*(VALUE(LEFT('Historique commandes'!M3:M52,2))>=11)*(VALUE(LEFT('Historique commandes'!M3:M52,2))<14)),0)>0.5),"✅ Créneau optimal",IF(=IFERROR(SUMPRODUCT(('Historique commandes'!C3:C52="Grab")*('Historique commandes'!M3:M52<>"")*(VALUE(LEFT('Historique commandes'!M3:M52,2))>=11)*(VALUE(LEFT('Historique commandes'!M3:M52,2))<14)*'Historique commandes'!E3:E52)/=SUMPRODUCT(('Historique commandes'!C3:C52="Grab")*('Historique commandes'!M3:M52<>"")*(VALUE(LEFT('Historique commandes'!M3:M52,2))>=11)*(VALUE(LEFT('Historique commandes'!M3:M52,2))<14)),"-")>AVERAGEIF('Historique commandes'!C3:C52,"Grab",'Historique commandes'!E3:E52)*1.1,"⚠️ Éviter si possible","🟡 Correct")))
B29: 🌤 Après-midi (14h-17h) | C29: =SUMPRODUCT(('Historique commandes'!C3:C52="Grab")*('Historique commandes'!M3:M52<>"")*(VALUE(LEFT('Historique commandes'!M3:M52,2))>=14)*(VALUE(LEFT('Historique commandes'!M3:M52,2))<17)) | D29: =IFERROR(SUMPRODUCT(('Historique commandes'!C3:C52="Grab")*('Historique commandes'!M3:M52<>"")*(VALUE(LEFT('Historique commandes'!M3:M52,2))>=14)*(VALUE(LEFT('Historique commandes'!M3:M52,2))<17)*'Historique commandes'!E3:E52)/=SUMPRODUCT(('Historique commandes'!C3:C52="Grab")*('Historique commandes'!M3:M52<>"")*(VALUE(LEFT('Historique commandes'!M3:M52,2))>=14)*(VALUE(LEFT('Historique commandes'!M3:M52,2))<17)),"-") | E29: =IFERROR(ABS(SUMPRODUCT(('Historique commandes'!C3:C52="Grab")*('Historique commandes'!M3:M52<>"")*(VALUE(LEFT('Historique commandes'!M3:M52,2))>=14)*(VALUE(LEFT('Historique commandes'!M3:M52,2))<17)*('Historique commandes'!F3:F52<0)*'Historique commandes'!F3:F52))/=SUMPRODUCT(('Historique commandes'!C3:C52="Grab")*('Historique commandes'!M3:M52<>"")*(VALUE(LEFT('Historique commandes'!M3:M52,2))>=14)*(VALUE(LEFT('Historique commandes'!M3:M52,2))<17)),0) | F29: =IFERROR(SUMPRODUCT(('Historique commandes'!C3:C52="Grab")*('Historique commandes'!M3:M52<>"")*(VALUE(LEFT('Historique commandes'!M3:M52,2))>=14)*(VALUE(LEFT('Historique commandes'!M3:M52,2))<17)*('Historique commandes'!I3:I52<>""))/=SUMPRODUCT(('Historique commandes'!C3:C52="Grab")*('Historique commandes'!M3:M52<>"")*(VALUE(LEFT('Historique commandes'!M3:M52,2))>=14)*(VALUE(LEFT('Historique commandes'!M3:M52,2))<17)),0) | G29: =IF(=SUMPRODUCT(('Historique commandes'!C3:C52="Grab")*('Historique commandes'!M3:M52<>"")*(VALUE(LEFT('Historique commandes'!M3:M52,2))>=14)*(VALUE(LEFT('Historique commandes'!M3:M52,2))<17))=0,"— Pas encore de données",IF(AND(=IFERROR(SUMPRODUCT(('Historique commandes'!C3:C52="Grab")*('Historique commandes'!M3:M52<>"")*(VALUE(LEFT('Historique commandes'!M3:M52,2))>=14)*(VALUE(LEFT('Historique commandes'!M3:M52,2))<17)*'Historique commandes'!E3:E52)/=SUMPRODUCT(('Historique commandes'!C3:C52="Grab")*('Historique commandes'!M3:M52<>"")*(VALUE(LEFT('Historique commandes'!M3:M52,2))>=14)*(VALUE(LEFT('Historique commandes'!M3:M52,2))<17)),"-")<AVERAGEIF('Historique commandes'!C3:C52,"Grab",'Historique commandes'!E3:E52),=IFERROR(SUMPRODUCT(('Historique commandes'!C3:C52="Grab")*('Historique commandes'!M3:M52<>"")*(VALUE(LEFT('Historique commandes'!M3:M52,2))>=14)*(VALUE(LEFT('Historique commandes'!M3:M52,2))<17)*('Historique commandes'!I3:I52<>""))/=SUMPRODUCT(('Historique commandes'!C3:C52="Grab")*('Historique commandes'!M3:M52<>"")*(VALUE(LEFT('Historique commandes'!M3:M52,2))>=14)*(VALUE(LEFT('Historique commandes'!M3:M52,2))<17)),0)>0.5),"✅ Créneau optimal",IF(=IFERROR(SUMPRODUCT(('Historique commandes'!C3:C52="Grab")*('Historique commandes'!M3:M52<>"")*(VALUE(LEFT('Historique commandes'!M3:M52,2))>=14)*(VALUE(LEFT('Historique commandes'!M3:M52,2))<17)*'Historique commandes'!E3:E52)/=SUMPRODUCT(('Historique commandes'!C3:C52="Grab")*('Historique commandes'!M3:M52<>"")*(VALUE(LEFT('Historique commandes'!M3:M52,2))>=14)*(VALUE(LEFT('Historique commandes'!M3:M52,2))<17)),"-")>AVERAGEIF('Historique commandes'!C3:C52,"Grab",'Historique commandes'!E3:E52)*1.1,"⚠️ Éviter si possible","🟡 Correct")))
B30: 🌆 Soir (17h-21h) | C30: =SUMPRODUCT(('Historique commandes'!C3:C52="Grab")*('Historique commandes'!M3:M52<>"")*(VALUE(LEFT('Historique commandes'!M3:M52,2))>=17)*(VALUE(LEFT('Historique commandes'!M3:M52,2))<21)) | D30: =IFERROR(SUMPRODUCT(('Historique commandes'!C3:C52="Grab")*('Historique commandes'!M3:M52<>"")*(VALUE(LEFT('Historique commandes'!M3:M52,2))>=17)*(VALUE(LEFT('Historique commandes'!M3:M52,2))<21)*'Historique commandes'!E3:E52)/=SUMPRODUCT(('Historique commandes'!C3:C52="Grab")*('Historique commandes'!M3:M52<>"")*(VALUE(LEFT('Historique commandes'!M3:M52,2))>=17)*(VALUE(LEFT('Historique commandes'!M3:M52,2))<21)),"-") | E30: =IFERROR(ABS(SUMPRODUCT(('Historique commandes'!C3:C52="Grab")*('Historique commandes'!M3:M52<>"")*(VALUE(LEFT('Historique commandes'!M3:M52,2))>=17)*(VALUE(LEFT('Historique commandes'!M3:M52,2))<21)*('Historique commandes'!F3:F52<0)*'Historique commandes'!F3:F52))/=SUMPRODUCT(('Historique commandes'!C3:C52="Grab")*('Historique commandes'!M3:M52<>"")*(VALUE(LEFT('Historique commandes'!M3:M52,2))>=17)*(VALUE(LEFT('Historique commandes'!M3:M52,2))<21)),0) | F30: =IFERROR(SUMPRODUCT(('Historique commandes'!C3:C52="Grab")*('Historique commandes'!M3:M52<>"")*(VALUE(LEFT('Historique commandes'!M3:M52,2))>=17)*(VALUE(LEFT('Historique commandes'!M3:M52,2))<21)*('Historique commandes'!I3:I52<>""))/=SUMPRODUCT(('Historique commandes'!C3:C52="Grab")*('Historique commandes'!M3:M52<>"")*(VALUE(LEFT('Historique commandes'!M3:M52,2))>=17)*(VALUE(LEFT('Historique commandes'!M3:M52,2))<21)),0) | G30: =IF(=SUMPRODUCT(('Historique commandes'!C3:C52="Grab")*('Historique commandes'!M3:M52<>"")*(VALUE(LEFT('Historique commandes'!M3:M52,2))>=17)*(VALUE(LEFT('Historique commandes'!M3:M52,2))<21))=0,"— Pas encore de données",IF(AND(=IFERROR(SUMPRODUCT(('Historique commandes'!C3:C52="Grab")*('Historique commandes'!M3:M52<>"")*(VALUE(LEFT('Historique commandes'!M3:M52,2))>=17)*(VALUE(LEFT('Historique commandes'!M3:M52,2))<21)*'Historique commandes'!E3:E52)/=SUMPRODUCT(('Historique commandes'!C3:C52="Grab")*('Historique commandes'!M3:M52<>"")*(VALUE(LEFT('Historique commandes'!M3:M52,2))>=17)*(VALUE(LEFT('Historique commandes'!M3:M52,2))<21)),"-")<AVERAGEIF('Historique commandes'!C3:C52,"Grab",'Historique commandes'!E3:E52),=IFERROR(SUMPRODUCT(('Historique commandes'!C3:C52="Grab")*('Historique commandes'!M3:M52<>"")*(VALUE(LEFT('Historique commandes'!M3:M52,2))>=17)*(VALUE(LEFT('Historique commandes'!M3:M52,2))<21)*('Historique commandes'!I3:I52<>""))/=SUMPRODUCT(('Historique commandes'!C3:C52="Grab")*('Historique commandes'!M3:M52<>"")*(VALUE(LEFT('Historique commandes'!M3:M52,2))>=17)*(VALUE(LEFT('Historique commandes'!M3:M52,2))<21)),0)>0.5),"✅ Créneau optimal",IF(=IFERROR(SUMPRODUCT(('Historique commandes'!C3:C52="Grab")*('Historique commandes'!M3:M52<>"")*(VALUE(LEFT('Historique commandes'!M3:M52,2))>=17)*(VALUE(LEFT('Historique commandes'!M3:M52,2))<21)*'Historique commandes'!E3:E52)/=SUMPRODUCT(('Historique commandes'!C3:C52="Grab")*('Historique commandes'!M3:M52<>"")*(VALUE(LEFT('Historique commandes'!M3:M52,2))>=17)*(VALUE(LEFT('Historique commandes'!M3:M52,2))<21)),"-")>AVERAGEIF('Historique commandes'!C3:C52,"Grab",'Historique commandes'!E3:E52)*1.1,"⚠️ Éviter si possible","🟡 Correct")))
B31: 🌙 Nuit (21h-0h) | C31: =SUMPRODUCT(('Historique commandes'!C3:C52="Grab")*('Historique commandes'!M3:M52<>"")*(VALUE(LEFT('Historique commandes'!M3:M52,2))>=21)*(VALUE(LEFT('Historique commandes'!M3:M52,2))<24)) | D31: =IFERROR(SUMPRODUCT(('Historique commandes'!C3:C52="Grab")*('Historique commandes'!M3:M52<>"")*(VALUE(LEFT('Historique commandes'!M3:M52,2))>=21)*(VALUE(LEFT('Historique commandes'!M3:M52,2))<24)*'Historique commandes'!E3:E52)/=SUMPRODUCT(('Historique commandes'!C3:C52="Grab")*('Historique commandes'!M3:M52<>"")*(VALUE(LEFT('Historique commandes'!M3:M52,2))>=21)*(VALUE(LEFT('Historique commandes'!M3:M52,2))<24)),"-") | E31: =IFERROR(ABS(SUMPRODUCT(('Historique commandes'!C3:C52="Grab")*('Historique commandes'!M3:M52<>"")*(VALUE(LEFT('Historique commandes'!M3:M52,2))>=21)*(VALUE(LEFT('Historique commandes'!M3:M52,2))<24)*('Historique commandes'!F3:F52<0)*'Historique commandes'!F3:F52))/=SUMPRODUCT(('Historique commandes'!C3:C52="Grab")*('Historique commandes'!M3:M52<>"")*(VALUE(LEFT('Historique commandes'!M3:M52,2))>=21)*(VALUE(LEFT('Historique commandes'!M3:M52,2))<24)),0) | F31: =IFERROR(SUMPRODUCT(('Historique commandes'!C3:C52="Grab")*('Historique commandes'!M3:M52<>"")*(VALUE(LEFT('Historique commandes'!M3:M52,2))>=21)*(VALUE(LEFT('Historique commandes'!M3:M52,2))<24)*('Historique commandes'!I3:I52<>""))/=SUMPRODUCT(('Historique commandes'!C3:C52="Grab")*('Historique commandes'!M3:M52<>"")*(VALUE(LEFT('Historique commandes'!M3:M52,2))>=21)*(VALUE(LEFT('Historique commandes'!M3:M52,2))<24)),0) | G31: =IF(=SUMPRODUCT(('Historique commandes'!C3:C52="Grab")*('Historique commandes'!M3:M52<>"")*(VALUE(LEFT('Historique commandes'!M3:M52,2))>=21)*(VALUE(LEFT('Historique commandes'!M3:M52,2))<24))=0,"— Pas encore de données",IF(AND(=IFERROR(SUMPRODUCT(('Historique commandes'!C3:C52="Grab")*('Historique commandes'!M3:M52<>"")*(VALUE(LEFT('Historique commandes'!M3:M52,2))>=21)*(VALUE(LEFT('Historique commandes'!M3:M52,2))<24)*'Historique commandes'!E3:E52)/=SUMPRODUCT(('Historique commandes'!C3:C52="Grab")*('Historique commandes'!M3:M52<>"")*(VALUE(LEFT('Historique commandes'!M3:M52,2))>=21)*(VALUE(LEFT('Historique commandes'!M3:M52,2))<24)),"-")<AVERAGEIF('Historique commandes'!C3:C52,"Grab",'Historique commandes'!E3:E52),=IFERROR(SUMPRODUCT(('Historique commandes'!C3:C52="Grab")*('Historique commandes'!M3:M52<>"")*(VALUE(LEFT('Historique commandes'!M3:M52,2))>=21)*(VALUE(LEFT('Historique commandes'!M3:M52,2))<24)*('Historique commandes'!I3:I52<>""))/=SUMPRODUCT(('Historique commandes'!C3:C52="Grab")*('Historique commandes'!M3:M52<>"")*(VALUE(LEFT('Historique commandes'!M3:M52,2))>=21)*(VALUE(LEFT('Historique commandes'!M3:M52,2))<24)),0)>0.5),"✅ Créneau optimal",IF(=IFERROR(SUMPRODUCT(('Historique commandes'!C3:C52="Grab")*('Historique commandes'!M3:M52<>"")*(VALUE(LEFT('Historique commandes'!M3:M52,2))>=21)*(VALUE(LEFT('Historique commandes'!M3:M52,2))<24)*'Historique commandes'!E3:E52)/=SUMPRODUCT(('Historique commandes'!C3:C52="Grab")*('Historique commandes'!M3:M52<>"")*(VALUE(LEFT('Historique commandes'!M3:M52,2))>=21)*(VALUE(LEFT('Historique commandes'!M3:M52,2))<24)),"-")>AVERAGEIF('Historique commandes'!C3:C52,"Grab",'Historique commandes'!E3:E52)*1.1,"⚠️ Éviter si possible","🟡 Correct")))
B34: TOP RESTAURANTS GRAB
B35: Restaurant | C35: Nb commandes | D35: Panier moyen (€) | E35: Économie moy. (€) | F35: Score moyen | G35: Verdict
B36: KFC | C36: =COUNTIFS('Historique commandes'!C3:C52,"Grab",'Historique commandes'!D3:D52,"KFC") | D36: =IFERROR(AVERAGEIFS('Historique commandes'!E3:E52,'Historique commandes'!C3:C52,"Grab",'Historique commandes'!D3:D52,"KFC"),"-") | E36: =IFERROR(ABS(AVERAGEIFS('Historique commandes'!F3:F52,'Historique commandes'!C3:C52,"Grab",'Historique commandes'!D3:D52,"KFC",'Historique commandes'!F3:F52,"<0")),0) | F36: =IFERROR(AVERAGEIFS('Historique commandes'!K3:K52,'Historique commandes'!C3:C52,"Grab",'Historique commandes'!D3:D52,"KFC"),"-") | G36: =IF(C36=0,"— Jamais commandé",IF(E36>=7,"⭐ Valeur excellente",IF(E36>=5,"👍 Bon rapport qualité/prix","💸 Optimisation possible")))
B37: McDonald's | C37: =COUNTIFS('Historique commandes'!C3:C52,"Grab",'Historique commandes'!D3:D52,"McDonald's") | D37: =IFERROR(AVERAGEIFS('Historique commandes'!E3:E52,'Historique commandes'!C3:C52,"Grab",'Historique commandes'!D3:D52,"McDonald's"),"-") | E37: =IFERROR(ABS(AVERAGEIFS('Historique commandes'!F3:F52,'Historique commandes'!C3:C52,"Grab",'Historique commandes'!D3:D52,"McDonald's",'Historique commandes'!F3:F52,"<0")),0) | F37: =IFERROR(AVERAGEIFS('Historique commandes'!K3:K52,'Historique commandes'!C3:C52,"Grab",'Historique commandes'!D3:D52,"McDonald's"),"-") | G37: =IF(C37=0,"— Jamais commandé",IF(E37>=7,"⭐ Valeur excellente",IF(E37>=5,"👍 Bon rapport qualité/prix","💸 Optimisation possible")))
B38: Sushi House | C38: =COUNTIFS('Historique commandes'!C3:C52,"Grab",'Historique commandes'!D3:D52,"Sushi House") | D38: =IFERROR(AVERAGEIFS('Historique commandes'!E3:E52,'Historique commandes'!C3:C52,"Grab",'Historique commandes'!D3:D52,"Sushi House"),"-") | E38: =IFERROR(ABS(AVERAGEIFS('Historique commandes'!F3:F52,'Historique commandes'!C3:C52,"Grab",'Historique commandes'!D3:D52,"Sushi House",'Historique commandes'!F3:F52,"<0")),0) | F38: =IFERROR(AVERAGEIFS('Historique commandes'!K3:K52,'Historique commandes'!C3:C52,"Grab",'Historique commandes'!D3:D52,"Sushi House"),"-") | G38: =IF(C38=0,"— Jamais commandé",IF(E38>=7,"⭐ Valeur excellente",IF(E38>=5,"👍 Bon rapport qualité/prix","💸 Optimisation possible")))
B39: Noodle Bar | C39: =COUNTIFS('Historique commandes'!C3:C52,"Grab",'Historique commandes'!D3:D52,"Noodle Bar") | D39: =IFERROR(AVERAGEIFS('Historique commandes'!E3:E52,'Historique commandes'!C3:C52,"Grab",'Historique commandes'!D3:D52,"Noodle Bar"),"-") | E39: =IFERROR(ABS(AVERAGEIFS('Historique commandes'!F3:F52,'Historique commandes'!C3:C52,"Grab",'Historique commandes'!D3:D52,"Noodle Bar",'Historique commandes'!F3:F52,"<0")),0) | F39: =IFERROR(AVERAGEIFS('Historique commandes'!K3:K52,'Historique commandes'!C3:C52,"Grab",'Historique commandes'!D3:D52,"Noodle Bar"),"-") | G39: =IF(C39=0,"— Jamais commandé",IF(E39>=7,"⭐ Valeur excellente",IF(E39>=5,"👍 Bon rapport qualité/prix","💸 Optimisation possible")))
B40: Pizza Hut | C40: =COUNTIFS('Historique commandes'!C3:C52,"Grab",'Historique commandes'!D3:D52,"Pizza Hut") | D40: =IFERROR(AVERAGEIFS('Historique commandes'!E3:E52,'Historique commandes'!C3:C52,"Grab",'Historique commandes'!D3:D52,"Pizza Hut"),"-") | E40: =IFERROR(ABS(AVERAGEIFS('Historique commandes'!F3:F52,'Historique commandes'!C3:C52,"Grab",'Historique commandes'!D3:D52,"Pizza Hut",'Historique commandes'!F3:F52,"<0")),0) | F40: =IFERROR(AVERAGEIFS('Historique commandes'!K3:K52,'Historique commandes'!C3:C52,"Grab",'Historique commandes'!D3:D52,"Pizza Hut"),"-") | G40: =IF(C40=0,"— Jamais commandé",IF(E40>=7,"⭐ Valeur excellente",IF(E40>=5,"👍 Bon rapport qualité/prix","💸 Optimisation possible")))
B41: Burger King | C41: =COUNTIFS('Historique commandes'!C3:C52,"Grab",'Historique commandes'!D3:D52,"Burger King") | D41: =IFERROR(AVERAGEIFS('Historique commandes'!E3:E52,'Historique commandes'!C3:C52,"Grab",'Historique commandes'!D3:D52,"Burger King"),"-") | E41: =IFERROR(ABS(AVERAGEIFS('Historique commandes'!F3:F52,'Historique commandes'!C3:C52,"Grab",'Historique commandes'!D3:D52,"Burger King",'Historique commandes'!F3:F52,"<0")),0) | F41: =IFERROR(AVERAGEIFS('Historique commandes'!K3:K52,'Historique commandes'!C3:C52,"Grab",'Historique commandes'!D3:D52,"Burger King"),"-") | G41: =IF(C41=0,"— Jamais commandé",IF(E41>=7,"⭐ Valeur excellente",IF(E41>=5,"👍 Bon rapport qualité/prix","💸 Optimisation possible")))
B42: Pad Thai | C42: =COUNTIFS('Historique commandes'!C3:C52,"Grab",'Historique commandes'!D3:D52,"Pad Thai") | D42: =IFERROR(AVERAGEIFS('Historique commandes'!E3:E52,'Historique commandes'!C3:C52,"Grab",'Historique commandes'!D3:D52,"Pad Thai"),"-") | E42: =IFERROR(ABS(AVERAGEIFS('Historique commandes'!F3:F52,'Historique commandes'!C3:C52,"Grab",'Historique commandes'!D3:D52,"Pad Thai",'Historique commandes'!F3:F52,"<0")),0) | F42: =IFERROR(AVERAGEIFS('Historique commandes'!K3:K52,'Historique commandes'!C3:C52,"Grab",'Historique commandes'!D3:D52,"Pad Thai"),"-") | G42: =IF(C42=0,"— Jamais commandé",IF(E42>=7,"⭐ Valeur excellente",IF(E42>=5,"👍 Bon rapport qualité/prix","💸 Optimisation possible")))
B43: Dim Sum Express | C43: =COUNTIFS('Historique commandes'!C3:C52,"Grab",'Historique commandes'!D3:D52,"Dim Sum Express") | D43: =IFERROR(AVERAGEIFS('Historique commandes'!E3:E52,'Historique commandes'!C3:C52,"Grab",'Historique commandes'!D3:D52,"Dim Sum Express"),"-") | E43: =IFERROR(ABS(AVERAGEIFS('Historique commandes'!F3:F52,'Historique commandes'!C3:C52,"Grab",'Historique commandes'!D3:D52,"Dim Sum Express",'Historique commandes'!F3:F52,"<0")),0) | F43: =IFERROR(AVERAGEIFS('Historique commandes'!K3:K52,'Historique commandes'!C3:C52,"Grab",'Historique commandes'!D3:D52,"Dim Sum Express"),"-") | G43: =IF(C43=0,"— Jamais commandé",IF(E43>=7,"⭐ Valeur excellente",IF(E43>=5,"👍 Bon rapport qualité/prix","💸 Optimisation possible")))
B46: DOIS-JE COMMANDER MAINTENANT ?
B47: Heure actuelle (HH:MM) | D47: =TEXT(NOW(),"HH:MM")
B48: Promos disponibles aujourd'hui | D48: =COUNTIFS('Suivi promotions'!A3:A40,"Grab",'Suivi promotions'!G3:G40,"Non",'Suivi promotions'!F3:F40,">="&TODAY())&" promo(s) Grab active(s)"
B49: Recommandation globale | D49: =IF(AND(VALUE(LEFT(D47,2))>=11,VALUE(LEFT(D47,2))<14,COUNTIFS('Suivi promotions'!A3:A40,"Grab",'Suivi promotions'!G3:G40,"Non",'Suivi promotions'!F3:F40,">="&TODAY())>0),"✅ Bon moment + promo dispo — Commander !",IF(AND(VALUE(LEFT(D47,2))>=14,VALUE(LEFT(D47,2))<17),"✅ Créneau Happy Hour potentiel — Vérifier promos",IF(OR(AND(VALUE(LEFT(D47,2))>=12,VALUE(LEFT(D47,2))<13),AND(VALUE(LEFT(D47,2))>=19,VALUE(LEFT(D47,2))<20)),"⚠️ Heure de pointe — Moins de promos, frais livraison plus élevés","🟡 Créneau neutre — Commander si nécessaire")))

Sheet Simulateur scénarios
B1: 🔢 SIMULATEUR — SCÉNARIOS D'OPTIMISATION GRAB
B2: Modifiez les cellules bleues pour simuler différentes combinaisons
B4: PARAMÈTRES DE BASE (modifier les valeurs bleues)
B5: Panier moyen habituel (€) | E5: 20
B6: Nb commandes par semaine | E6: 4
B7: Frais livraison moyen sans abonnement (€) | E7: 2.5
B8: Coût abonnement Grab Unlimited (€/mois) | E8: 5.99
B9: Taux de réduction moyen avec promo (%) | E9: 0.15
B12: COMPARAISON DE 4 SCÉNARIOS SUR 1 MOIS
B13: Indicateur | C13: Scénario 1 (Aucune optim.) | D13: Scénario 2 (Promos seulement) | E13: Scénario 3 (Abonnement seul) | F13: Scénario 4 (Promos + Abo)
B14: Nb commandes / mois | C14: =ROUND(E6*4.33,0) | D14: =ROUND(E6*4.33,0) | E14: =ROUND(E6*4.33,0) | F14: =ROUND(E6*4.33,0)
B15: Dépense panier brut (€) | C15: =ROUND(E5*E6*4.33,2) | D15: =ROUND(E5*(1-E9)*E6*4.33,2) | E15: =ROUND(E5*E6*4.33,2) | F15: =ROUND(E5*(1-E9)*E6*4.33,2)
B16: Frais de livraison (€) | C16: =ROUND(E7*E6*4.33,2) | D16: =ROUND(E7*E6*4.33,2) | E16: 0.00 | F16: 0.00
B17: Coût abonnement (€) | C17: 0.00 | D17: 0.00 | E17: =E8 | F17: =E8
B18: TOTAL MENSUEL (€) | C18: =C15+C16+C17 | D18: =D15+D16+D17 | E18: =E15+E16+E17 | F18: =F15+F16+F17
B19: Économie vs Scénario 1 (€) | C19: — | D19: =C18-D18 | E19: =C18-E18 | F19: =C18-F18
B20: Économie vs Scénario 1 (%) | C20: — | D20: =IFERROR((C18-D18)/C18,0) | E20: =IFERROR((C18-E18)/C18,0) | F20: =IFERROR((C18-F18)/C18,0)
B21: Coût par commande (€) | C21: =IFERROR(C18/C14,0) | D21: =IFERROR(D18/D14,0) | E21: =IFERROR(E18/E14,0) | F21: =IFERROR(F18/F14,0)
B24: SIMULATEUR UNE COMMANDE — OPTIMISATION EN TEMPS RÉEL
B25: Montant du panier (€) | E25: 22 | G25: ← modifier
B26: Frais livraison (€) | E26: 2.5 | G26: ← modifier
B27: Taux de réduction promo (%) | E27: 0.15 | G27: ← modifier
B28: Livraison gratuite ? (1=oui, 0=non) | E28: 0 | G28: ← modifier
B29: Abonnement actif ? (1=oui, 0=non) | E29: 0 | G29: ← modifier
B31: Prix sans optimisation (€) | E31: =E25+E26
B32: Prix avec promo seule (€) | E32: =E25*(1-E27)+E26
B33: Prix avec livraison gratuite (€) | E33: =E25*(1-E27)+E26*(1-E28)
B34: Prix optimisé complet (€) | E34: =E25*(1-E27)+E26*(1-MAX(E28,E29))
B35: Économie réalisée (€) | E35: =E31-E34
B36: Économie (%) | E36: =IFERROR((E31-E34)/E31,0)

Sheet Historique commandes
A1: 📦 HISTORIQUE DES COMMANDES
A2: Date | B2: Jour | C2: Plateforme | D2: Restaurant | E2: Montant brut (€) | F2: Réduction (€) | G2: Frais livraison (€) | H2: Total payé (€) | I2: Code promo | J2: Notes | K2: Score optim. /10 | L2: Verdict | M2: Heure commande
A3: 2026-04-07 | B3: Lun | C3: Grab | D3: KFC | E3: 18 | F3: -2.7 | G3: 0 | H3: =E3+F3+G3 | I3: GRAB15 | J3: Livraison offerte atteinte | K3: =IF(E3="","",MIN(10,IF(F3<0,3,0)+IF(G3=0,2,0)+IF(I3<>"",2,0)+IF(H3<AVERAGE('Historique commandes'!H3:H52)*0.9,2,0)+IF(OR(ISNUMBER(SEARCH("h",J3)),J3<>""),1,0))) | L3: =IF(K3="","",IF(K3>=8,"🟢 Excellent",IF(K3>=5,"🟡 Correct","🔴 À améliorer"))) | M3: 12:30
A4: 2026-04-08 | B4: Mar | C4: Wolt | D4: Burger King | E4: 15.5 | F4: 0 | G4: 1.99 | H4: =E4+F4+G4 | K4: =IF(E4="","",MIN(10,IF(F4<0,3,0)+IF(G4=0,2,0)+IF(I4<>"",2,0)+IF(H4<AVERAGE('Historique commandes'!H3:H52)*0.9,2,0)+IF(OR(ISNUMBER(SEARCH("h",J4)),J4<>""),1,0))) | L4: =IF(K4="","",IF(K4>=8,"🟢 Excellent",IF(K4>=5,"🟡 Correct","🔴 À améliorer")))
A5: 2026-04-09 | B5: Mer | C5: Grab | D5: Sushi House | E5: 22 | F5: -4.4 | G5: 0 | H5: =E5+F5+G5 | I5: SUSHI20 | J5: -20% restaurant partenaire | K5: =IF(E5="","",MIN(10,IF(F5<0,3,0)+IF(G5=0,2,0)+IF(I5<>"",2,0)+IF(H5<AVERAGE('Historique commandes'!H3:H52)*0.9,2,0)+IF(OR(ISNUMBER(SEARCH("h",J5)),J5<>""),1,0))) | L5: =IF(K5="","",IF(K5>=8,"🟢 Excellent",IF(K5>=5,"🟡 Correct","🔴 À améliorer"))) | M5: 13:00
A6: 2026-04-10 | B6: Jeu | C6: Wolt | D6: Pizza Palace | E6: 14 | F6: 0 | G6: 2.5 | H6: =E6+F6+G6 | K6: =IF(E6="","",MIN(10,IF(F6<0,3,0)+IF(G6=0,2,0)+IF(I6<>"",2,0)+IF(H6<AVERAGE('Historique commandes'!H3:H52)*0.9,2,0)+IF(OR(ISNUMBER(SEARCH("h",J6)),J6<>""),1,0))) | L6: =IF(K6="","",IF(K6>=8,"🟢 Excellent",IF(K6>=5,"🟡 Correct","🔴 À améliorer")))
A7: 2026-04-11 | B7: Ven | C7: Grab | D7: Noodle Bar | E7: 19.5 | F7: -3.9 | G7: 0 | H7: =E7+F7+G7 | I7: GRABVIP | K7: =IF(E7="","",MIN(10,IF(F7<0,3,0)+IF(G7=0,2,0)+IF(I7<>"",2,0)+IF(H7<AVERAGE('Historique commandes'!H3:H52)*0.9,2,0)+IF(OR(ISNUMBER(SEARCH("h",J7)),J7<>""),1,0))) | L7: =IF(K7="","",IF(K7>=8,"🟢 Excellent",IF(K7>=5,"🟡 Correct","🔴 À améliorer"))) | M7: 19:45
A8: 2026-04-12 | B8: Sam | C8: Wolt | D8: Thai Express | E8: 16 | F8: -3.2 | G8: 0 | H8: =E8+F8+G8 | I8: WOLT20 | J8: Happy Hour | K8: =IF(E8="","",MIN(10,IF(F8<0,3,0)+IF(G8=0,2,0)+IF(I8<>"",2,0)+IF(H8<AVERAGE('Historique commandes'!H3:H52)*0.9,2,0)+IF(OR(ISNUMBER(SEARCH("h",J8)),J8<>""),1,0))) | L8: =IF(K8="","",IF(K8>=8,"🟢 Excellent",IF(K8>=5,"🟡 Correct","🔴 À améliorer"))) | M8: 14:15
A9: 2026-04-13 | B9: Dim | C9: Grab | D9: McDo | E9: 12 | F9: 0 | G9: 2.5 | H9: =E9+F9+G9 | J9: Commande rapide | K9: =IF(E9="","",MIN(10,IF(F9<0,3,0)+IF(G9=0,2,0)+IF(I9<>"",2,0)+IF(H9<AVERAGE('Historique commandes'!H3:H52)*0.9,2,0)+IF(OR(ISNUMBER(SEARCH("h",J9)),J9<>""),1,0))) | L9: =IF(K9="","",IF(K9>=8,"🟢 Excellent",IF(K9>=5,"🟡 Correct","🔴 À améliorer"))) | M9: 20:10
H10: =IF(E10="","",E10+F10+G10) | K10: =IF(E10="","",MIN(10,IF(F10<0,3,0)+IF(G10=0,2,0)+IF(I10<>"",2,0)+IF(H10<AVERAGE('Historique commandes'!H3:H52)*0.9,2,0)+IF(OR(ISNUMBER(SEARCH("h",J10)),J10<>""),1,0))) | L10: =IF(K10="","",IF(K10>=8,"🟢 Excellent",IF(K10>=5,"🟡 Correct","🔴 À améliorer")))
H11: =IF(E11="","",E11+F11+G11) | K11: =IF(E11="","",MIN(10,IF(F11<0,3,0)+IF(G11=0,2,0)+IF(I11<>"",2,0)+IF(H11<AVERAGE('Historique commandes'!H3:H52)*0.9,2,0)+IF(OR(ISNUMBER(SEARCH("h",J11)),J11<>""),1,0))) | L11: =IF(K11="","",IF(K11>=8,"🟢 Excellent",IF(K11>=5,"🟡 Correct","🔴 À améliorer")))
H12: =IF(E12="","",E12+F12+G12) | K12: =IF(E12="","",MIN(10,IF(F12<0,3,0)+IF(G12=0,2,0)+IF(I12<>"",2,0)+IF(H12<AVERAGE('Historique commandes'!H3:H52)*0.9,2,0)+IF(OR(ISNUMBER(SEARCH("h",J12)),J12<>""),1,0))) | L12: =IF(K12="","",IF(K12>=8,"🟢 Excellent",IF(K12>=5,"🟡 Correct","🔴 À améliorer")))
H13: =IF(E13="","",E13+F13+G13) | K13: =IF(E13="","",MIN(10,IF(F13<0,3,0)+IF(G13=0,2,0)+IF(I13<>"",2,0)+IF(H13<AVERAGE('Historique commandes'!H3:H52)*0.9,2,0)+IF(OR(ISNUMBER(SEARCH("h",J13)),J13<>""),1,0))) | L13: =IF(K13="","",IF(K13>=8,"🟢 Excellent",IF(K13>=5,"🟡 Correct","🔴 À améliorer")))
H14: =IF(E14="","",E14+F14+G14) | K14: =IF(E14="","",MIN(10,IF(F14<0,3,0)+IF(G14=0,2,0)+IF(I14<>"",2,0)+IF(H14<AVERAGE('Historique commandes'!H3:H52)*0.9,2,0)+IF(OR(ISNUMBER(SEARCH("h",J14)),J14<>""),1,0))) | L14: =IF(K14="","",IF(K14>=8,"🟢 Excellent",IF(K14>=5,"🟡 Correct","🔴 À améliorer")))
H15: =IF(E15="","",E15+F15+G15) | K15: =IF(E15="","",MIN(10,IF(F15<0,3,0)+IF(G15=0,2,0)+IF(I15<>"",2,0)+IF(H15<AVERAGE('Historique commandes'!H3:H52)*0.9,2,0)+IF(OR(ISNUMBER(SEARCH("h",J15)),J15<>""),1,0))) | L15: =IF(K15="","",IF(K15>=8,"🟢 Excellent",IF(K15>=5,"🟡 Correct","🔴 À améliorer")))
H16: =IF(E16="","",E16+F16+G16) | K16: =IF(E16="","",MIN(10,IF(F16<0,3,0)+IF(G16=0,2,0)+IF(I16<>"",2,0)+IF(H16<AVERAGE('Historique commandes'!H3:H52)*0.9,2,0)+IF(OR(ISNUMBER(SEARCH("h",J16)),J16<>""),1,0))) | L16: =IF(K16="","",IF(K16>=8,"🟢 Excellent",IF(K16>=5,"🟡 Correct","🔴 À améliorer")))
H17: =IF(E17="","",E17+F17+G17) | K17: =IF(E17="","",MIN(10,IF(F17<0,3,0)+IF(G17=0,2,0)+IF(I17<>"",2,0)+IF(H17<AVERAGE('Historique commandes'!H3:H52)*0.9,2,0)+IF(OR(ISNUMBER(SEARCH("h",J17)),J17<>""),1,0))) | L17: =IF(K17="","",IF(K17>=8,"🟢 Excellent",IF(K17>=5,"🟡 Correct","🔴 À améliorer")))
H18: =IF(E18="","",E18+F18+G18) | K18: =IF(E18="","",MIN(10,IF(F18<0,3,0)+IF(G18=0,2,0)+IF(I18<>"",2,0)+IF(H18<AVERAGE('Historique commandes'!H3:H52)*0.9,2,0)+IF(OR(ISNUMBER(SEARCH("h",J18)),J18<>""),1,0))) | L18: =IF(K18="","",IF(K18>=8,"🟢 Excellent",IF(K18>=5,"🟡 Correct","🔴 À améliorer")))
H19: =IF(E19="","",E19+F19+G19) | K19: =IF(E19="","",MIN(10,IF(F19<0,3,0)+IF(G19=0,2,0)+IF(I19<>"",2,0)+IF(H19<AVERAGE('Historique commandes'!H3:H52)*0.9,2,0)+IF(OR(ISNUMBER(SEARCH("h",J19)),J19<>""),1,0))) | L19: =IF(K19="","",IF(K19>=8,"🟢 Excellent",IF(K19>=5,"🟡 Correct","🔴 À améliorer")))
H20: =IF(E20="","",E20+F20+G20) | K20: =IF(E20="","",MIN(10,IF(F20<0,3,0)+IF(G20=0,2,0)+IF(I20<>"",2,0)+IF(H20<AVERAGE('Historique commandes'!H3:H52)*0.9,2,0)+IF(OR(ISNUMBER(SEARCH("h",J20)),J20<>""),1,0))) | L20: =IF(K20="","",IF(K20>=8,"🟢 Excellent",IF(K20>=5,"🟡 Correct","🔴 À améliorer")))
H21: =IF(E21="","",E21+F21+G21) | K21: =IF(E21="","",MIN(10,IF(F21<0,3,0)+IF(G21=0,2,0)+IF(I21<>"",2,0)+IF(H21<AVERAGE('Historique commandes'!H3:H52)*0.9,2,0)+IF(OR(ISNUMBER(SEARCH("h",J21)),J21<>""),1,0))) | L21: =IF(K21="","",IF(K21>=8,"🟢 Excellent",IF(K21>=5,"🟡 Correct","🔴 À améliorer")))
H22: =IF(E22="","",E22+F22+G22) | K22: =IF(E22="","",MIN(10,IF(F22<0,3,0)+IF(G22=0,2,0)+IF(I22<>"",2,0)+IF(H22<AVERAGE('Historique commandes'!H3:H52)*0.9,2,0)+IF(OR(ISNUMBER(SEARCH("h",J22)),J22<>""),1,0))) | L22: =IF(K22="","",IF(K22>=8,"🟢 Excellent",IF(K22>=5,"🟡 Correct","🔴 À améliorer")))
H23: =IF(E23="","",E23+F23+G23) | K23: =IF(E23="","",MIN(10,IF(F23<0,3,0)+IF(G23=0,2,0)+IF(I23<>"",2,0)+IF(H23<AVERAGE('Historique commandes'!H3:H52)*0.9,2,0)+IF(OR(ISNUMBER(SEARCH("h",J23)),J23<>""),1,0))) | L23: =IF(K23="","",IF(K23>=8,"🟢 Excellent",IF(K23>=5,"🟡 Correct","🔴 À améliorer")))
H24: =IF(E24="","",E24+F24+G24) | K24: =IF(E24="","",MIN(10,IF(F24<0,3,0)+IF(G24=0,2,0)+IF(I24<>"",2,0)+IF(H24<AVERAGE('Historique commandes'!H3:H52)*0.9,2,0)+IF(OR(ISNUMBER(SEARCH("h",J24)),J24<>""),1,0))) | L24: =IF(K24="","",IF(K24>=8,"🟢 Excellent",IF(K24>=5,"🟡 Correct","🔴 À améliorer")))
H25: =IF(E25="","",E25+F25+G25) | K25: =IF(E25="","",MIN(10,IF(F25<0,3,0)+IF(G25=0,2,0)+IF(I25<>"",2,0)+IF(H25<AVERAGE('Historique commandes'!H3:H52)*0.9,2,0)+IF(OR(ISNUMBER(SEARCH("h",J25)),J25<>""),1,0))) | L25: =IF(K25="","",IF(K25>=8,"🟢 Excellent",IF(K25>=5,"🟡 Correct","🔴 À améliorer")))
H26: =IF(E26="","",E26+F26+G26) | K26: =IF(E26="","",MIN(10,IF(F26<0,3,0)+IF(G26=0,2,0)+IF(I26<>"",2,0)+IF(H26<AVERAGE('Historique commandes'!H3:H52)*0.9,2,0)+IF(OR(ISNUMBER(SEARCH("h",J26)),J26<>""),1,0))) | L26: =IF(K26="","",IF(K26>=8,"🟢 Excellent",IF(K26>=5,"🟡 Correct","🔴 À améliorer")))
H27: =IF(E27="","",E27+F27+G27) | K27: =IF(E27="","",MIN(10,IF(F27<0,3,0)+IF(G27=0,2,0)+IF(I27<>"",2,0)+IF(H27<AVERAGE('Historique commandes'!H3:H52)*0.9,2,0)+IF(OR(ISNUMBER(SEARCH("h",J27)),J27<>""),1,0))) | L27: =IF(K27="","",IF(K27>=8,"🟢 Excellent",IF(K27>=5,"🟡 Correct","🔴 À améliorer")))
H28: =IF(E28="","",E28+F28+G28) | K28: =IF(E28="","",MIN(10,IF(F28<0,3,0)+IF(G28=0,2,0)+IF(I28<>"",2,0)+IF(H28<AVERAGE('Historique commandes'!H3:H52)*0.9,2,0)+IF(OR(ISNUMBER(SEARCH("h",J28)),J28<>""),1,0))) | L28: =IF(K28="","",IF(K28>=8,"🟢 Excellent",IF(K28>=5,"🟡 Correct","🔴 À améliorer")))
H29: =IF(E29="","",E29+F29+G29) | K29: =IF(E29="","",MIN(10,IF(F29<0,3,0)+IF(G29=0,2,0)+IF(I29<>"",2,0)+IF(H29<AVERAGE('Historique commandes'!H3:H52)*0.9,2,0)+IF(OR(ISNUMBER(SEARCH("h",J29)),J29<>""),1,0))) | L29: =IF(K29="","",IF(K29>=8,"🟢 Excellent",IF(K29>=5,"🟡 Correct","🔴 À améliorer")))
H30: =IF(E30="","",E30+F30+G30) | K30: =IF(E30="","",MIN(10,IF(F30<0,3,0)+IF(G30=0,2,0)+IF(I30<>"",2,0)+IF(H30<AVERAGE('Historique commandes'!H3:H52)*0.9,2,0)+IF(OR(ISNUMBER(SEARCH("h",J30)),J30<>""),1,0))) | L30: =IF(K30="","",IF(K30>=8,"🟢 Excellent",IF(K30>=5,"🟡 Correct","🔴 À améliorer")))
H31: =IF(E31="","",E31+F31+G31) | K31: =IF(E31="","",MIN(10,IF(F31<0,3,0)+IF(G31=0,2,0)+IF(I31<>"",2,0)+IF(H31<AVERAGE('Historique commandes'!H3:H52)*0.9,2,0)+IF(OR(ISNUMBER(SEARCH("h",J31)),J31<>""),1,0))) | L31: =IF(K31="","",IF(K31>=8,"🟢 Excellent",IF(K31>=5,"🟡 Correct","🔴 À améliorer")))
H32: =IF(E32="","",E32+F32+G32) | K32: =IF(E32="","",MIN(10,IF(F32<0,3,0)+IF(G32=0,2,0)+IF(I32<>"",2,0)+IF(H32<AVERAGE('Historique commandes'!H3:H52)*0.9,2,0)+IF(OR(ISNUMBER(SEARCH("h",J32)),J32<>""),1,0))) | L32: =IF(K32="","",IF(K32>=8,"🟢 Excellent",IF(K32>=5,"🟡 Correct","🔴 À améliorer")))
H33: =IF(E33="","",E33+F33+G33) | K33: =IF(E33="","",MIN(10,IF(F33<0,3,0)+IF(G33=0,2,0)+IF(I33<>"",2,0)+IF(H33<AVERAGE('Historique commandes'!H3:H52)*0.9,2,0)+IF(OR(ISNUMBER(SEARCH("h",J33)),J33<>""),1,0))) | L33: =IF(K33="","",IF(K33>=8,"🟢 Excellent",IF(K33>=5,"🟡 Correct","🔴 À améliorer")))
H34: =IF(E34="","",E34+F34+G34) | K34: =IF(E34="","",MIN(10,IF(F34<0,3,0)+IF(G34=0,2,0)+IF(I34<>"",2,0)+IF(H34<AVERAGE('Historique commandes'!H3:H52)*0.9,2,0)+IF(OR(ISNUMBER(SEARCH("h",J34)),J34<>""),1,0))) | L34: =IF(K34="","",IF(K34>=8,"🟢 Excellent",IF(K34>=5,"🟡 Correct","🔴 À améliorer")))
H35: =IF(E35="","",E35+F35+G35) | K35: =IF(E35="","",MIN(10,IF(F35<0,3,0)+IF(G35=0,2,0)+IF(I35<>"",2,0)+IF(H35<AVERAGE('Historique commandes'!H3:H52)*0.9,2,0)+IF(OR(ISNUMBER(SEARCH("h",J35)),J35<>""),1,0))) | L35: =IF(K35="","",IF(K35>=8,"🟢 Excellent",IF(K35>=5,"🟡 Correct","🔴 À améliorer")))
H36: =IF(E36="","",E36+F36+G36) | K36: =IF(E36="","",MIN(10,IF(F36<0,3,0)+IF(G36=0,2,0)+IF(I36<>"",2,0)+IF(H36<AVERAGE('Historique commandes'!H3:H52)*0.9,2,0)+IF(OR(ISNUMBER(SEARCH("h",J36)),J36<>""),1,0))) | L36: =IF(K36="","",IF(K36>=8,"🟢 Excellent",IF(K36>=5,"🟡 Correct","🔴 À améliorer")))
H37: =IF(E37="","",E37+F37+G37) | K37: =IF(E37="","",MIN(10,IF(F37<0,3,0)+IF(G37=0,2,0)+IF(I37<>"",2,0)+IF(H37<AVERAGE('Historique commandes'!H3:H52)*0.9,2,0)+IF(OR(ISNUMBER(SEARCH("h",J37)),J37<>""),1,0))) | L37: =IF(K37="","",IF(K37>=8,"🟢 Excellent",IF(K37>=5,"🟡 Correct","🔴 À améliorer")))
H38: =IF(E38="","",E38+F38+G38) | K38: =IF(E38="","",MIN(10,IF(F38<0,3,0)+IF(G38=0,2,0)+IF(I38<>"",2,0)+IF(H38<AVERAGE('Historique commandes'!H3:H52)*0.9,2,0)+IF(OR(ISNUMBER(SEARCH("h",J38)),J38<>""),1,0))) | L38: =IF(K38="","",IF(K38>=8,"🟢 Excellent",IF(K38>=5,"🟡 Correct","🔴 À améliorer")))
H39: =IF(E39="","",E39+F39+G39) | K39: =IF(E39="","",MIN(10,IF(F39<0,3,0)+IF(G39=0,2,0)+IF(I39<>"",2,0)+IF(H39<AVERAGE('Historique commandes'!H3:H52)*0.9,2,0)+IF(OR(ISNUMBER(SEARCH("h",J39)),J39<>""),1,0))) | L39: =IF(K39="","",IF(K39>=8,"🟢 Excellent",IF(K39>=5,"🟡 Correct","🔴 À améliorer")))
H40: =IF(E40="","",E40+F40+G40) | K40: =IF(E40="","",MIN(10,IF(F40<0,3,0)+IF(G40=0,2,0)+IF(I40<>"",2,0)+IF(H40<AVERAGE('Historique commandes'!H3:H52)*0.9,2,0)+IF(OR(ISNUMBER(SEARCH("h",J40)),J40<>""),1,0))) | L40: =IF(K40="","",IF(K40>=8,"🟢 Excellent",IF(K40>=5,"🟡 Correct","🔴 À améliorer")))
...

Sheet Suivi promotions
A1: 🎁 SUIVI DES PROMOTIONS
A2: Plateforme | B2: Type promo | C2: Code / Source | D2: Valeur | E2: Condition min. | F2: Expire le | G2: Utilisé ? | H2: Économie réelle (€) | I2: Statut
A3: Grab | B3: % commande | C3: GRAB15 | D3: -15% | E3: Min. 18€ | F3: 2026-04-20 | G3: Oui | H3: -3.9 | I3: =IF(G3="Oui","✓ Utilisé",IF(F3<TODAY(),"⚠ Expirée","✅ Disponible"))
A4: Grab | B4: % commande | C4: SUSHI20 | D4: -20% | E4: Min. 15€ | F4: 2026-04-25 | G4: Oui | H4: -4.4 | I4: =IF(G4="Oui","✓ Utilisé",IF(F4<TODAY(),"⚠ Expirée","✅ Disponible"))
A5: Grab | B5: % commande | C5: GRABVIP | D5: -20% | E5: Min. 18€ | F5: 2026-04-30 | G5: Oui | H5: -3.9 | I5: =IF(G5="Oui","✓ Utilisé",IF(F5<TODAY(),"⚠ Expirée","✅ Disponible"))
A6: Wolt | B6: % commande | C6: WOLT20 | D6: -20% | E6: Min. 15€ | F6: 2026-04-15 | G6: Oui | H6: -3.2 | I6: =IF(G6="Oui","✓ Utilisé",IF(F6<TODAY(),"⚠ Expirée","✅ Disponible"))
A7: Wolt | B7: Livraison gratuite | C7: APP_NOTIF | D7: 0€ liv. | E7: Min. 20€ | F7: 2026-04-18 | G7: Non | H7: 0 | I7: =IF(G7="Oui","✓ Utilisé",IF(F7<TODAY(),"⚠ Expirée","✅ Disponible"))
A8: Grab | B8: Livraison gratuite | C8: GRABFREE | D8: 0€ liv. | E8: Min. 12€ | F8: 2026-04-30 | G8: Non | H8: 0 | I8: =IF(G8="Oui","✓ Utilisé",IF(F8<TODAY(),"⚠ Expirée","✅ Disponible"))
A9: Wolt | B9: Remise fixe | C9: WOLT5 | D9: -5€ | E9: Min. 25€ | F9: 2026-05-01 | G9: Non | H9: 0 | I9: =IF(G9="Oui","✓ Utilisé",IF(F9<TODAY(),"⚠ Expirée","✅ Disponible"))
A10: Grab | B10: Happy Hour | C10: APP | D10: -25% | E10: 14h-16h | F10: 2026-04-30 | G10: Non | H10: 0 | I10: =IF(G10="Oui","✓ Utilisé",IF(F10<TODAY(),"⚠ Expirée","✅ Disponible"))
I11: =IF(G11="Oui","✓ Utilisé",IF(AND(F11<>"",F11<TODAY()),"⚠ Expirée",IF(F11="","","✅ Disponible")))
I12: =IF(G12="Oui","✓ Utilisé",IF(AND(F12<>"",F12<TODAY()),"⚠ Expirée",IF(F12="","","✅ Disponible")))
I13: =IF(G13="Oui","✓ Utilisé",IF(AND(F13<>"",F13<TODAY()),"⚠ Expirée",IF(F13="","","✅ Disponible")))
I14: =IF(G14="Oui","✓ Utilisé",IF(AND(F14<>"",F14<TODAY()),"⚠ Expirée",IF(F14="","","✅ Disponible")))
I15: =IF(G15="Oui","✓ Utilisé",IF(AND(F15<>"",F15<TODAY()),"⚠ Expirée",IF(F15="","","✅ Disponible")))
I16: =IF(G16="Oui","✓ Utilisé",IF(AND(F16<>"",F16<TODAY()),"⚠ Expirée",IF(F16="","","✅ Disponible")))
I17: =IF(G17="Oui","✓ Utilisé",IF(AND(F17<>"",F17<TODAY()),"⚠ Expirée",IF(F17="","","✅ Disponible")))
I18: =IF(G18="Oui","✓ Utilisé",IF(AND(F18<>"",F18<TODAY()),"⚠ Expirée",IF(F18="","","✅ Disponible")))
I19: =IF(G19="Oui","✓ Utilisé",IF(AND(F19<>"",F19<TODAY()),"⚠ Expirée",IF(F19="","","✅ Disponible")))
I20: =IF(G20="Oui","✓ Utilisé",IF(AND(F20<>"",F20<TODAY()),"⚠ Expirée",IF(F20="","","✅ Disponible")))
I21: =IF(G21="Oui","✓ Utilisé",IF(AND(F21<>"",F21<TODAY()),"⚠ Expirée",IF(F21="","","✅ Disponible")))
I22: =IF(G22="Oui","✓ Utilisé",IF(AND(F22<>"",F22<TODAY()),"⚠ Expirée",IF(F22="","","✅ Disponible")))
... I40: =IF(G40="Oui","✓ Utilisé",IF(AND(F40<>"",F40<TODAY()),"⚠ Expirée",IF(F40="","","✅ Disponible")))
